Traceback (most recent call last):
  File "C:\Users\fredy\miniconda3\lib\site-packages\jupyter_cache\executors\utils.py", line 58, in single_nb_execution
    executenb(
  File "C:\Users\fredy\miniconda3\lib\site-packages\nbclient\client.py", line 1204, in execute
    return NotebookClient(nb=nb, resources=resources, km=km, **kwargs).execute()
  File "C:\Users\fredy\miniconda3\lib\site-packages\nbclient\util.py", line 84, in wrapped
    return just_run(coro(*args, **kwargs))
  File "C:\Users\fredy\miniconda3\lib\site-packages\nbclient\util.py", line 62, in just_run
    return loop.run_until_complete(coro)
  File "C:\Users\fredy\miniconda3\lib\asyncio\base_events.py", line 647, in run_until_complete
    return future.result()
  File "C:\Users\fredy\miniconda3\lib\site-packages\nbclient\client.py", line 663, in async_execute
    await self.async_execute_cell(
  File "C:\Users\fredy\miniconda3\lib\site-packages\nbclient\client.py", line 965, in async_execute_cell
    await self._check_raise_for_error(cell, cell_index, exec_reply)
  File "C:\Users\fredy\miniconda3\lib\site-packages\nbclient\client.py", line 862, in _check_raise_for_error
    raise CellExecutionError.from_cell_and_msg(cell, exec_reply_content)
nbclient.exceptions.CellExecutionError: An error occurred while executing the following cell:
------------------
from prettytable import PrettyTable
def df_explore(df):
    #Description table of the main characteristics of each column from a dataset
    print( 'Shape: ', df.shape)

    t = PrettyTable(['Column',
                     'Type',
                     'Non-Null',
                     'Nulls',
                     'Unique',
                     ])

    for c in df.columns:
        t.add_row([c,
                   df[c].dtype,
                   len(df[c])-np.sum(df[c].isna()),
                   np.sum(df[c].isna()),
                   np.count_nonzero(df[c].unique()),

                  ])
    print(t)
    print()
    return


------------------

[1;31m---------------------------------------------------------------------------[0m
[1;31mModuleNotFoundError[0m                       Traceback (most recent call last)
Cell [1;32mIn[6], line 1[0m
[1;32m----> 1[0m [38;5;28;01mfrom[39;00m [38;5;21;01mprettytable[39;00m [38;5;28;01mimport[39;00m PrettyTable
[0;32m      2[0m [38;5;28;01mdef[39;00m [38;5;21mdf_explore[39m(df):
[0;32m      3[0m     [38;5;66;03m#Description table of the main characteristics of each column from a dataset[39;00m
[0;32m      4[0m     [38;5;28mprint[39m( [38;5;124m'[39m[38;5;124mShape: [39m[38;5;124m'[39m, df[38;5;241m.[39mshape)

[1;31mModuleNotFoundError[0m: No module named 'prettytable'
ModuleNotFoundError: No module named 'prettytable'

